<?xml version="1.0"?>
<robot name="hexarover" xmlns:xacro="http://www.ros.org/wiki/xacro">

  <material name="silver">
    <color rgba="0.8 0.8 0.8 1"/>
  </material>
  <material name="black">
    <color rgba="0.1 0.1 0.1 1"/>
  </material>
  <material name="red">
    <color rgba="1 0 0 1"/>
  </material>

  <link name="base_link">
    <visual>
      <origin xyz="0 0 0.04" rpy="0 0 0"/> <geometry>
        <box size="0.45 0.16 0.08"/> </geometry>
      <material name="silver"/>
    </visual>
    <collision>
      <origin xyz="0 0 0.04" rpy="0 0 0"/>
      <geometry>
        <box size="0.45 0.16 0.08"/>
      </geometry>
    </collision>
    <inertial>
      <mass value="5.0"/>
      <inertia ixx="0.04" ixy="0" ixz="0" iyy="0.1" iyz="0" izz="0.1"/>
    </inertial>
  </link>

  <xacro:macro name="wheel" params="prefix side x_pos y_pos friction">
    <link name="${prefix}_${side}_wheel">
      <visual>
        <geometry>
          <cylinder radius="0.065" length="0.07"/> </geometry>
        <material name="black"/>
      </visual>
      <collision>
        <geometry>
          <cylinder radius="0.065" length="0.07"/>
        </geometry>
      </collision>
      <inertial>
        <mass value="0.8"/>
        <inertia ixx="0.001" ixy="0" ixz="0" iyy="0.001" iyz="0" izz="0.001"/>
      </inertial>
    </link>

    <joint name="${prefix}_${side}_wheel_joint" type="continuous">
      <parent link="base_link"/>
      <child link="${prefix}_${side}_wheel"/>
      <origin xyz="${x_pos} ${y_pos} 0" rpy="-1.5707 0 0"/> 
      <axis xyz="0 0 1"/>
    </joint>

    <gazebo reference="${prefix}_${side}_wheel">
      <mu1>${friction}</mu1> <mu2>${friction}</mu2> <material>Gazebo/Black</material>
    </gazebo>
  </xacro:macro>

  <xacro:wheel prefix="mid" side="left"  x_pos="0"     y_pos="0.13" friction="1.0"/>
  <xacro:wheel prefix="mid" side="right" x_pos="0"     y_pos="-0.13" friction="1.0"/>

  <xacro:wheel prefix="front" side="left"  x_pos="0.16"  y_pos="0.13" friction="0.2"/>
  <xacro:wheel prefix="front" side="right" x_pos="0.16"  y_pos="-0.13" friction="0.2"/>

  <xacro:wheel prefix="rear" side="left"  x_pos="-0.16" y_pos="0.13" friction="0.2"/>
  <xacro:wheel prefix="rear" side="right" x_pos="-0.16" y_pos="-0.13" friction="0.2"/>


  <link name="lidar_link">
    <visual>
      <geometry>
        <cylinder radius="0.035" length="0.04"/>
      </geometry>
      <material name="red"/>
    </visual>
    <collision>
      <geometry>
        <cylinder radius="0.035" length="0.04"/>
      </geometry>
    </collision>
    <inertial>
      <mass value="0.1"/>
      <inertia ixx="0.0001" ixy="0" ixz="0" iyy="0.0001" iyz="0" izz="0.0001"/>
    </inertial>
  </link>

  <joint name="lidar_joint" type="fixed">
    <parent link="base_link"/>
    <child link="lidar_link"/>
    <origin xyz="0.05 0 0.10" rpy="0 0 0"/> 
  </joint>


  <gazebo>
    <plugin filename="gz-sim-diff-drive-system" name="gz::sim::systems::DiffDrive">
      <left_joint>mid_left_wheel_joint</left_joint>
      <right_joint>mid_right_wheel_joint</right_joint>
      <wheel_separation>0.26</wheel_separation>
      <wheel_radius>0.065</wheel_radius>
      <topic>cmd_vel</topic>
      <max_linear_acceleration>2.0</max_linear_acceleration>
    </plugin>

    <plugin filename="gz-sim-sensors-system" name="gz::sim::systems::Sensors">
      <render_engine>ogre2</render_engine>
    </plugin>

    <plugin filename="gz-sim-joint-state-publisher-system" name="gz::sim::systems::JointStatePublisher">
      <topic>joint_states</topic> <update_rate>30</update_rate>
    </plugin>
  </gazebo>

  <gazebo reference="lidar_link">
    <sensor name="lidar" type="gpu_lidar">
      <pose>0 0 0 0 0 0</pose>
      <always_on>true</always_on>
      <visualize>true</visualize>
      <update_rate>10</update_rate>
      <ray>
        <scan>
          <horizontal>
            <samples>360</samples>
            <resolution>1</resolution>
            <min_angle>-3.14</min_angle>
            <max_angle>3.14</max_angle>
          </horizontal>
        </scan>
        <range>
          <min>0.15</min> <max>10.0</max>
        </range>
      </ray>
      <topic>scan</topic>
      <gz_frame_id>lidar_link</gz_frame_id>
    </sensor>
  </gazebo>

</robot>
